Workbook

Sheet Hoja1
A1: NOMBRE | B1: CELULAR | C1: MAIL | D1: BASICO | E1: BASICO INT | F1: NIVEL II | G1: NIVEL III | H1: PHOTOS I | I1: PHOTOS II | J1: PHOTOS 3 | K1: PHOTOS ByN | L1: Photoshop Pieles | M1: JORNADA ROD. | N1: PROYECTO | O1: LA MIRADA | P1: POETICAS | Q1: LR
A2: Abel Gomez | C2: abelg608@gmail.com | H2: Mayo 23 | I2: Junio 23
A3: Abi Cima | Q3: Abril 25
A4: Abi Cima | H4: Mayo 25
A5: Abi Cima | I5: Junio 25
A6: Abi Cima | K6: Junio 25
A7: Adela Rizzolli | B7: 154044-6018 | C7: adelarizzolli@gmail.com | M7: 42064
A8: Adrian Cavallaro | H8: Abril 24
A9: Adrian Cavallaro | I9: Mayo 24
A10: Adrian Cavallaro | J10: Junio 24
A11: Adrian Gaitan | B11: 1161286168 | C11: adriburza@hotmail.com | H11: Enero 23 | I11: Julio 23
A12: Adrian Gaitan | Q12: 45985
A13: Adrian Larcamon | B13: 11 6722 4784 | C13: elmonoliso@gmail.com | K13: Jun 21 online
A14: Adriana Balcarce | B14: 11 5101 4190 | C14: =HYPERLINK("mailto:adrianabalcarce@fibertel.com.ar","adrianabalcarce@fibertel.com.ar") -> adrianabalcarce@fibertel.com.ar | F14: 40789 | H14: 41277
A15: Adriana Bauab | B15: 17 4927 2975 | C15: adribauab@gmail.com | E15: Ene 21
A16: Adriana Caprari | C16: adriana.caprari@gmail.com | E16: 41642
A17: Adriana Chillo | H17: Julio 24 | I17: Agosto 24
A18: Adriana Chillo | J18: Sept 24
A19: Adriana Cordoba | C19: adricor_a@hotmail.com | H19: Agosto 20 online | I19: Sept 20 online | J19: Oct 20 online
A20: Adriana Cuesta Suarez | B20: 17 3595 5586 | C20: anacuestasuarez@yahoo.com.ar | D20: 40819
A21: Adriana Daher | B21: 17 55937700 | C21: adri.daher@gmail.com | D21: Agos 21
A22: Adriana Nenadovik | H22: Marzo 25
A23: Adriana Olivares | H23: Agosto 23 | I23: Sept 23
A24: Adriana Sol | B24: 1565155460 | C24: soladria@gmail.com | H24: Abril 21 online | I24: Junio 21 online | J24: Julio 21 online | K24: Sept 21 online | P24: Abril 23
A25: Adriana Sol | P25: Julio 24
A26: Agustin Buldo | C26: agustincrevatin@gmail.com | H26: Junio 23
A27: Agustín Castro | C27: agustingcastro@hotmail.com | E27: Sept 19
A28: Agustin Romero | H28: Enero 25
A29: Agustin Romero | I29: 45713
A30: Agustina Castañon | B30: 1565519410 | C30: castanon.agustina@gmail.com | D30: 43299
A31: Agustina Liendo | B31: 1161175618 | C31: aguspaula00@gmail.com | H31: Abril 21 online
A32: Agustina Melo | B32: 236-154303074 | C32: agustinamelo87@gmail.com | D32: Agos 19 | H32: Agosto 20 online | I32: Sept 20 online | J32: Oct 20 online | K32: Nov 20 online
A33: Agustina Sicoli | B33: 1169495127 | C33: agustinascicoliok@gmail.com | H33: Enero 24
A34: Agustina Sicoli | H34: Enero 24
A35: Agustina Spinelli | B35: 1561786042 | C35: s3.agustina@gmail.com | E35: 43149
A36: Agustina Wortman Jofre | C36: =HYPERLINK("mailto:gugaa.2@hotmail.com","gugaa.2@hotmail.com") -> gugaa.2@hotmail.com | E36: 41306
A37: Alanis Gustavo Ceferino | B37: 92214950413 | C37: gusalaniz@hotmail.com | D37: octubre 21 online | H37: 45252 | I37: enero 23
A38: Albert Feifer | C38: 17855731 dni
A39: Albert Feifer | Q39: 45833
A40: Alberto Crincoli | Q40: 45985
...

Sheet Hoja2
A1: #N/A
A2: =VLOOKUP(#REF!,Hoja1!A:A,TRUE) -> #REF!
A3: =VLOOKUP(Hoja1!A3,Hoja1!A:A,TRUE) -> Abi Cima
A4: =VLOOKUP(Hoja1!A4,Hoja1!A:A,TRUE) -> Abi Cima
A5: =VLOOKUP(#REF!,Hoja1!A:A,TRUE) -> #REF!
A6: =VLOOKUP(Hoja1!A5,Hoja1!A:A,TRUE) -> Abi Cima
A7: =VLOOKUP(Hoja1!A6,Hoja1!A:A,TRUE) -> Abi Cima
A8: =VLOOKUP(Hoja1!A7,Hoja1!A:A,TRUE) -> Adela Rizzolli
A9: =VLOOKUP(Hoja1!A8,Hoja1!A:A,TRUE) -> Adrian Cavallaro
A10: =VLOOKUP(Hoja1!A9,Hoja1!A:A,TRUE) -> Adrian Cavallaro
A11: =VLOOKUP(Hoja1!A10,Hoja1!A:A,TRUE) -> Adrian Cavallaro
A12: =VLOOKUP(Hoja1!A11,Hoja1!A:A,TRUE) -> Adrian Gaitan
A13: =VLOOKUP(Hoja1!A12,Hoja1!A:A,TRUE) -> Adrian Gaitan
A14: =VLOOKUP(#REF!,Hoja1!A:A,TRUE) -> #REF!
A15: =VLOOKUP(Hoja1!A13,Hoja1!A:A,TRUE) -> Adrian Larcamon
A16: =VLOOKUP(#REF!,Hoja1!A:A,TRUE) -> #REF!
A17: =VLOOKUP(Hoja1!A14,Hoja1!A:A,TRUE) -> Adriana Balcarce
A18: =VLOOKUP(Hoja1!A15,Hoja1!A:A,TRUE) -> Adriana Bauab
A19: =VLOOKUP(Hoja1!A16,Hoja1!A:A,TRUE) -> Adriana Caprari

Sheet Hoja3
